Workbook

Sheet Manufacturing Information
A1: employer_name | B1: job_title | C1: salary_raw | D1: salary_min | E1: salary_max | F1: platform | G1: position_link | H1: career_website
A2: Tesla | B2: Internship, Controls Engineer, Manufacturing (Fall 2025) | C2: null | D2: null | E2: null | F2: Handshake | G2: N/A | H2: Tesla Careers
A3: Tesla | B3: Internship, Equipment Engineer, Manufacturing (Winter/Spring 2026) | C3: null | D3: null | E3: null | F3: Handshake | G3: N/A | H3: Tesla Careers
A4: Tesla | B4: Internship, Construction Project Management, Infrastructure (Fall 2025) | C4: null | D4: null | E4: null | F4: Handshake | G4: N/A | H4: Tesla Careers
A5: Tesla | B5: Internship, 3D Generalist, Vehicle User Interface (Summer 2025) | C5: null | D5: null | E5: null | F5: Handshake | G5: N/A | H5: Tesla Careers
A6: Tesla | B6: Sr. Industrial Engineer | C6: null | D6: null | E6: null | F6: Handshake | G6: N/A | H6: Tesla Careers
A7: Tesla | B7: Internship, IT Operations Intern, Infrastructure Engineering (Fall 2025) | C7: null | D7: null | E7: null | F7: Handshake | G7: N/A | H7: Tesla Careers
A8: Tesla | B8: Internship, Security Services Coordinator, Security Systems Engineering (Fall 2025) | C8: null | D8: null | E8: null | F8: Handshake | G8: N/A | H8: Tesla Careers
A9: Tesla | B9: Internship, Architecture & Structural Engineer, Infrastructure (Fall 2025) | C9: null | D9: null | E9: null | F9: Handshake | G9: N/A | H9: Tesla Careers
A10: Tesla | B10: Internship, Architecture & Structural Engineer, Infrastructure (Winter/Spring 2026) | C10: null | D10: null | E10: null | F10: Handshake | G10: N/A | H10: Tesla Careers
A11: Tesla | B11: Internship, Software Validation Engineer, Vehicle Firmware (Fall 2025) | C11: null | D11: null | E11: null | F11: Handshake | G11: N/A | H11: Tesla Careers
A12: Tesla | B12: Entry Level Chemical Operator | C12: null | D12: null | E12: null | F12: Handshake | G12: N/A | H12: Tesla Careers
... A140: ASML | B140: Quality Engineering Co-Op - Spring 2026 | C140: null | D140: null | E140: null | F140: Handshake | G140: N/A | H140: ASML Careers
A141: Dexcom | B141: Senior Manager of Systems Engineering - Hardware & Firmware | C141: $164,200.00 - $273,600.00 | D141: =TRIM(LEFT($C141, FIND("-", $C141)-1)) -> $164,200.00 | E141: =TRIM(MID($C141, FIND("-", $C141)+1, LEN($C141))) -> $273,600.00 | F141: Website | G141: https://careers.dexcom.com/careers?domain=dexcom.com&start=0&location=San+Diego%2C+CA%2C+United+States&pid=38527152&sort_by=distance&filter_distance=80&filter_include_remote=1 | H141: Dexcom Careers and Job Opportunities
A142: Dexcom | B142: Senior Medical Device Engineer | C142: $105,800.00 - $176,300.00 | D142: =TRIM(LEFT($C142, FIND("-", $C142)-1)) -> $105,800.00 | E142: =TRIM(MID($C142, FIND("-", $C142)+1, LEN($C142))) -> $176,300.00 | F142: Website | G142: https://careers.dexcom.com/careers?domain=dexcom.com&start=0&location=San+Diego%2C+CA%2C+United+States&pid=38528658&sort_by=distance&filter_distance=80&filter_include_remote=1 | H142: Dexcom Careers and Job Opportunities
A143: Dexcom | B143: Product Manager | C143: $122,500.00 - $204,100.00 | D143: =TRIM(LEFT($C143, FIND("-", $C143)-1)) -> $122,500.00 | E143: =TRIM(MID($C143, FIND("-", $C143)+1, LEN($C143))) -> $204,100.00 | F143: Website | G143: https://careers.dexcom.com/careers?domain=dexcom.com&start=0&location=San+Diego%2C+CA%2C+United+States&pid=38600257&sort_by=distance&filter_distance=80&filter_include_remote=1 | H143: Dexcom Careers and Job Opportunities
A144: Dexcom | B144: Sr. Research Scientist, AI Experience (Data Scientist 3) | C144: $116,600.00 - $194,400.00 | D144: =TRIM(LEFT($C144, FIND("-", $C144)-1)) -> $116,600.00 | E144: =TRIM(MID($C144, FIND("-", $C144)+1, LEN($C144))) -> $194,400.00 | F144: Website | G144: https://careers.dexcom.com/careers?domain=dexcom.com&start=0&location=San+Diego%2C+CA%2C+United+States&pid=38634309&sort_by=distance&filter_distance=80&filter_include_remote=1 | H144: Dexcom Careers and Job Opportunities
A145: Dexcom | B145: Commercial Pricing Analyst | C145: $61,900.00 - $103,100.00 | D145: =TRIM(LEFT($C145, FIND("-", $C145)-1)) -> $61,900.00 | E145: =TRIM(MID($C145, FIND("-", $C145)+1, LEN($C145))) -> $103,100.00 | F145: Website | G145: https://careers.dexcom.com/careers?domain=dexcom.com&start=0&location=San+Diego%2C+CA%2C+United+States&pid=38634681&sort_by=distance&filter_distance=80&filter_include_remote=1 | H145: Dexcom Careers and Job Opportunities
A146: Dexcom | B146: Staff Process Engineer | C146: $111,100.00 - $185,100.00 | D146: =TRIM(LEFT($C146, FIND("-", $C146)-1)) -> $111,100.00 | E146: =TRIM(MID($C146, FIND("-", $C146)+1, LEN($C146))) -> $185,100.00 | F146: Website | G146: https://careers.dexcom.com/careers?domain=dexcom.com&start=0&location=San+Diego%2C+CA%2C+United+States&pid=38650202&sort_by=distance&filter_distance=80&filter_include_remote=1 | H146: Dexcom Careers and Job Opportunities
A147: Dexcom | B147: Staff Process Engineer | C147: $111,100.00 - $185,100.00 | D147: =TRIM(LEFT($C147, FIND("-", $C147)-1)) -> $111,100.00 | E147: =TRIM(MID($C147, FIND("-", $C147)+1, LEN($C147))) -> $185,100.00 | F147: Website | G147: https://careers.dexcom.com/careers?domain=dexcom.com&start=0&location=San+Diego%2C+CA%2C+United+States&pid=38650202&sort_by=distance&filter_distance=80&filter_include_remote=1 | H147: Dexcom Careers and Job Opportunities
A148: Dexcom | B148: Director of Medical Device Engineering - Sensor Development | C148: $190,100.00 - $316,800.00 | D148: =TRIM(LEFT($C148, FIND("-", $C148)-1)) -> $190,100.00 | E148: =TRIM(MID($C148, FIND("-", $C148)+1, LEN($C148))) -> $316,800.00 | F148: Website | G148: https://careers.dexcom.com/careers?domain=dexcom.com&start=0&location=San+Diego%2C+CA%2C+United+States&pid=38689354&sort_by=distance&filter_distance=80&filter_include_remote=1 | H148: Dexcom Careers and Job Opportunities
A149: Dexcom | B149: Sr Manager Molding Engineering | C149: $149,000.00 - $248,300.00 | D149: =TRIM(LEFT($C149, FIND("-", $C149)-1)) -> $149,000.00 | E149: =TRIM(MID($C149, FIND("-", $C149)+1, LEN($C149))) -> $248,300.00 | F149: Website | G149: https://careers.dexcom.com/careers?domain=dexcom.com&start=0&location=San+Diego%2C+CA%2C+United+States&pid=38691824&sort_by=distance&filter_distance=80&filter_include_remote=1 | H149: Dexcom Careers and Job Opportunities
A150: Dexcom | B150: Principal Engineer - Head of Sensor Production Support | C150: $181,000.00 - $301,600.00 | D150: =TRIM(LEFT($C150, FIND("-", $C150)-1)) -> $181,000.00 | E150: =TRIM(MID($C150, FIND("-", $C150)+1, LEN($C150))) -> $301,600.00 | F150: Website | G150: https://careers.dexcom.com/careers?domain=dexcom.com&start=0&location=San+Diego%2C+CA%2C+United+States&pid=38067926&sort_by=distance&filter_distance=80&filter_include_remote=1 | H150: Dexcom Careers and Job Opportunities
A151: Dexcom | B151: Senior Staff Systems Engineer | C151: $149,000.00 - $248,300.00 | D151: =TRIM(LEFT($C151, FIND("-", $C151)-1)) -> $149,000.00 | E151: =TRIM(MID($C151, FIND("-", $C151)+1, LEN($C151))) -> $248,300.00 | F151: Website | G151: https://careers.dexcom.com/careers?domain=dexcom.com&start=0&location=San+Diego%2C+CA%2C+United+States&pid=38258935&sort_by=distance&filter_distance=80&filter_include_remote=1 | H151: Dexcom Careers and Job Opportunities
A152: Dexcom | B152: Senior Systems Engineer - Hardware Platforms | C152: $111,100.00 - $185,100.00 | D152: =TRIM(LEFT($C152, FIND("-", $C152)-1)) -> $111,100.00 | E152: =TRIM(MID($C152, FIND("-", $C152)+1, LEN($C152))) -> $185,100.00 | F152: Website | G152: https://careers.dexcom.com/careers?domain=dexcom.com&start=0&location=San+Diego%2C+CA%2C+United+States&pid=38259335&sort_by=distance&filter_distance=80&filter_include_remote=1 | H152: Dexcom Careers and Job Opportunities
... A222: Dexcom | B222: Sr Lead Patient Support Services Analyst | C222: $135,100.00 - $225,100.00 | D222: =TRIM(LEFT($C222, FIND("-", $C222)-1)) -> $135,100.00 | E222: =TRIM(MID($C222, FIND("-", $C222)+1, LEN($C222))) -> $225,100.00 | F222: Website | G222: https://careers.dexcom.com/careers?domain=dexcom.com&start=70&location=San+Diego%2C+CA%2C+United+States&pid=39049356&sort_by=distance&filter_distance=80&filter_include_remote=1 | H222: Dexcom Careers and Job Opportunities
A223: Procter & Gamble | B223: Corporation Aviation Seminar | C223: null | D223: null | E223: null | F223: Website | G223: N/A | H223: P&G Careers
A224: Procter & Gamble | B224: Corporation Aviation Seminar - Seminar | C224: null | D224: null | E224: null | F224: Website | G224: N/A | H224: P&G Careers
A225: Procter & Gamble | B225: Data Scientist | C225: null | D225: null | E225: null | F225: Website | G225: N/A | H225: P&G Careers
A226: Procter & Gamble | B226: Site Digital IT Manager (2026 Grads) | C226: null | D226: null | E226: null | F226: Website | G226: N/A | H226: P&G Careers
A227: Procter & Gamble | B227: Masters Data Science Internship | C227: null | D227: null | E227: null | F227: Website | G227: N/A | H227: P&G Careers
A228: Procter & Gamble | B228: Advanced Analytics & Insights (Consumer & Market Knowledge) Internship - Summer 2026 | C228: null | D228: null | E228: null | F228: Website | G228: N/A | H228: P&G Careers
A229: Procter & Gamble | B229: Analytics & Insights (Consumer & Market Knowledge) Internship - Summer 2026 | C229: null | D229: null | E229: null | F229: Website | G229: N/A | H229: P&G Careers
A230: Procter & Gamble | B230: Sales Internship - Summer 2026 | C230: null | D230: null | E230: null | F230: Website | G230: N/A | H230: P&G Careers
A231: Procter & Gamble | B231: Marketing Technology Intern | C231: null | D231: null | E231: null | F231: Website | G231: N/A | H231: P&G Careers
A232: Procter & Gamble | B232: Site IT Operations Intern | C232: null | D232: null | E232: null | F232: Website | G232: N/A | H232: P&G Careers
A233: Procter & Gamble | B233: Human Resources Internship | C233: null | D233: null | E233: null | F233: Website | G233: N/A | H233: P&G Careers
A234: Procter & Gamble | B234: IT Engineer Internship | C234: null | D234: null | E234: null | F234: Website | G234: N/A | H234: P&G Careers
... A244: Procter & Gamble | B244: Research & Development Engineer Intern | C244: null | D244: null | E244: null | F244: Website | G244: N/A | H244: P&G Careers
A245: Frito-Lay | B245: Sanitor - Part-Time - 1st Shift | C245: 53081.6 | D245: 53081.6 | E245: 53081.6 | F245: Website | G245: https://portal.fritolayemployment.com/fritocareers/JobDetail?jobId=504286&recommendation=&jobName=Sanitor+-+Part-Time+-+1st+Shift&source=&tags= | H245: Frito-Lay Careers
...

Sheet Additional Notes + Log
B1: 45992 | C1: Monday Day 1 | D1: Notes
A2: Number of Postings | B2: Company Name | D2: All provided active job postings are in the last 12 months
A3: =COUNTIF('Manufacturing Information'!A:A, $B3) -> 61 | B3: Tesla | C3: Complete | D3: Handshake companies, including Tesla, ResMed, Oldcastle Infrastructure, General Atomics, and ASML, had not provided salaries in their postings
A4: =COUNTIF('Manufacturing Information'!A:A, $B4) -> 18 | B4: ResMed | C4: Complete
A5: =COUNTIF('Manufacturing Information'!A:A, $B5) -> 12 | B5: Oldcastle Infrastructure | C5: Complete
A6: =COUNTIF('Manufacturing Information'!A:A, $B6) -> 7 | B6: General Atomics | C6: Complete
A7: =COUNTIF('Manufacturing Information'!A:A, $B7) -> 41 | B7: ASML | C7: Complete
A8: =COUNTIF('Manufacturing Information'!A:A, $B8) -> 22 | B8: Procter & Gamble | C8: Complete | D8: Tesla, ResMed, Oldcastyle, General Atomics, ASML showed up in Handshake Report Filtering, Procter & Gamble did not but had Handshake listings
A9: =COUNTIF('Manufacturing Information'!A:A, $B9) -> 82 | B9: Dexcom | C9: Complete | D9: None posted on Handshake, posted on website, the following companies for day 2 will be all through website
A10: TODAY TOTAL
A11: =SUM(A3:A9) -> 243
B12: 45993 | C12: Tuesday Day 2 | D12: Notes
A13: =COUNTIF('Manufacturing Information'!A:A, $B13) -> 20 | B13: Frito-Lay | C13: Complete | D13: For some, hourly wage was given, salary was calculated by hourly wage * 2080 hours to simulate an annual salary assuming a standard 40 hour work week
A14: =COUNTIF('Manufacturing Information'!A:A, $B14) -> 0 | B14: LiDestri Food & Drink | C14: Complete | D14: https://lidestrifoods.com/careers None listed in Fresno
A15: =COUNTIF('Manufacturing Information'!A:A, $B15) -> 0 | B15: Busseto Foods, Inc. | C15: Complete | D15: https://busseto.com/careers/career-opportunities has no listings
A16: =COUNTIF('Manufacturing Information'!A:A, $B16) -> 2 | B16: Gusmer Enterprises, Inc. | C16: Complete
A17: =COUNTIF('Manufacturing Information'!A:A, $B17) -> 135 | B17: Boeing | C17: Complete | D17: https://jobs.boeing.com/search-jobs/Los%20Angeles%2C%20CA/185/4/6252001-5332921-5368381-5368361/34x05223/-118x24368/50/2 87
A18: =COUNTIF('Manufacturing Information'!A:A, $B18) -> 0 | B18: RCM Industries | C18: Complete | D18: https://www.paycomonline.net/v4/ats/web.php/jobs None listed in Los Angeles region
A19: =COUNTIF('Manufacturing Information'!A:A, $B19) -> 3 | B19: Kaiser Aluminum | C19: Complete
A20: =COUNTIF('Manufacturing Information'!A:A, $B20) -> 0 | B20: Spreckels Sugar Co., Inc. | C20: Complete | D20: https://recruiting2.ultipro.com/SOU1047SMBSC/JobBoard/660f759a-4cc9-435c-bbe9-4bf35aecfda4/?q=&o=postedDateDesc 0 opportunities available
A21: =COUNTIF('Manufacturing Information'!A:A, $B21) -> 0 | B21: Statevolt | C21: Complete | D21: https://statevolt.com/careers/ would have to contact a Statevolt representative to find current openings and application process
A22: =COUNTIF('Manufacturing Information'!A:A, $B22) -> 0 | B22: Rayotek Scientific, Inc. | C22: Complete | D22: https://www.linkedin.com/company/rayotek-scientific-llc/jobs/ no jobs posted
A23: =COUNTIF('Manufacturing Information'!A:A, $B23) -> 0 | B23: Tolar Manufacturing Company | C23: Complete | D23: https://tolarmfg.com/who-we-are/work-for-us/ any open positions aren't listed
A24: =COUNTIF('Manufacturing Information'!A:A, $B24) -> 5 | B24: Stanislaus Food Products Co. | C24: Complete
A25: =COUNTIF('Manufacturing Information'!A:A, $B25) -> 0 | B25: Plum Organics | C25: Complete | D25: https://www.plumorganics.com/?s=careers no results found
A26: =COUNTIF('Manufacturing Information'!A:A, $B26) -> 0 | B26: Fast Trak Fabrication | C26: Complete | D26: None found
A27: =COUNTIF('Manufacturing Information'!A:A, $B27) -> 19 | B27: GrayMatter Robotics | C27: Complete | D27: 19 https://jobs.ashbyhq.com/graymatter-robotics
A28: =COUNTIF('Manufacturing Information'!A:A, $B28) -> 2 | B28: Gallo Glass Company | C28: Complete
A29: =COUNTIF('Manufacturing Information'!A:A, $B29) -> 8 | B29: California Dairies, Inc. | C29: Complete
A30: =COUNTIF('Manufacturing Information'!A:A, $B30) -> 5 | B30: Golden State Foods | C30: Complete
A31: TODAY TOTAL
A32: =SUM(A13:A31) -> 199
A33: For reproducibility and workflow, Additional Notes + Log was added for explanations, Data Dictionary for understanding variables, and calculated salary if given hourly wage
A34: TOTAL TOTAL
A35: =COUNTA('Manufacturing Information'!A:A) -> 443

Sheet Data Dictionary
A1: Name of Variable | B1: Description | C1: Type
A2: employer_name | B2: The name of the employer | C2: String
A3: job_title | B3: The job title | C3: String
A4: salary_raw | B4: The provided (or calculated) salary in the posting if applicable; for data science purposes, we won't be using this column; it is purely informational | C4: $, double
A5: salary_min | B5: The provided (or calculated) salary lowest end range, or if the salary is a fixed number, then this is where that value goes | C5: $, double
A6: salary_max | B6: The provided (or calculated) salary highest end range; this column is only helpful if salary_min is not equal to salary_max, since this is for ranges, not a fixed salary | C6: $, double
A7: platform | B7: If this information was provided by either Handshake or directly from the careers website | C7: String
A8: position_link | B8: Link to job posting (if applicable) for reference | C8: String
A9: career_website | B9: Link to employers careers website | C9: String

Sheet Calculated Salary (If Hourly Wa
A1: References
A2: Position in Sheet 1 | B2: Hourly Wage | C2: Salary End | D2: Calculation Cell | E2: Usable
A3: 245 | B3: 25.52 | C3: Min/Max | D3: =$B3*2080 -> 53081.6 | E3: 53081
A4: 246 | B4: 23.05 | C4: Min/Max | D4: =$B4*2080 -> 47944 | E4: 47944
A5: 256 | B5: 24 | C5: Min/Max | D5: =$B5*2080 -> 49920 | E5: 47944
A6: 257 | B6: 26.2 | C6: Min/Max | D6: =$B6*2080 -> 54496 | E6: 54496
A7: 258 | B7: 24 | C7: Min/Max | D7: =$B7*2080 -> 49920 | E7: 47944
A8: 259 | B8: 25.4 | C8: Min/Max | D8: =$B8*2080 -> 52832 | E8: 52832
A9: 260 | B9: 24.36 | C9: Min/Max | D9: =$B9*2080 -> 50668.8 | E9: 50668.8
A10: 261 | B10: 19.5 | C10: Min/Max | D10: =$B10*2080 -> 40560 | E10: 40560
A11: 262 | B11: 19.1 | C11: Min/Max | D11: =$B11*2080 -> 39728 | E11: 39728
A12: 263 | B12: 18.45 | C12: Min/Max | D12: =$B12*2080 -> 38376 | E12: 38376
A13: 264 | B13: 32.3 | C13: Min/Max | D13: =$B13*2080 -> 67184 | E13: 67184
A14: 265 | B14: 28 | C14: Min | D14: =$B14*2080 -> 58240 | E14: 58240
B15: 32 | C15: Max | D15: =$B15*2080 -> 66560 | E15: 66560
A16: 266 | B16: 30 | C16: Min | D16: =$B16*2080 -> 62400 | E16: 62400
B17: 35 | C17: Max | D17: =$B17*2080 -> 72800 | E17: 72800
A18: 269 | B18: 30.47 | C18: Min | D18: =$B18*2080 -> 63377.6 | E18: 63377.6
B19: 33.87 | C19: Max | D19: =$B19*2080 -> 70449.6 | E19: 70449.6
A20: 274 | B20: 30.37 | C20: Min/Max | D20: =$B20*2080 -> 63169.6 | E20: 63169.6
A21: 275 | B21: 26.25 | C21: Min/Max | D21: =$B21*2080 -> 54600 | E21: 54600
A22: 284 | B22: 30 | C22: Min | D22: =$B22*2080 -> 62400 | E22: 62400
B23: 40 | C23: Max | D23: =$B23*2080 -> 83200 | E23: 83200
A24: 286 | B24: 20 | C24: Min | D24: =$B24*2080 -> 41600 | E24: 41600
B25: 30 | C25: Max | D25: =$B25*2080 -> 62400 | E25: 62400
A26: 290 | B26: 35 | C26: Min | D26: =$B26*2080 -> 72800 | E26: 72800
B27: 45 | C27: Max | D27: =$B27*2080 -> 93600 | E27: 93600
A28: 291 | B28: 30 | C28: Min | D28: =$B28*2080 -> 62400 | E28: 62400
B29: 40 | C29: Max | D29: =$B29*2080 -> 83200 | E29: 83200
A30: 299 | B30: 35 | C30: Min | D30: =$B30*2080 -> 72800 | E30: 72800
B31: 45 | C31: Max | D31: =$B31*2080 -> 93600 | E31: 93600
A32: 302 | B32: 21.75 | C32: Min | D32: =$B32*2080 -> 45240 | E32: 45240
B33: 22.5 | C33: Max | D33: =$B33*2080 -> 46800 | E33: 46800
A34: 303 | B34: 39.04 | C34: Min/Max | D34: =$B34*2080 -> 81203.2 | E34: 81203.2
A35: 308 | B35: 40 | C35: Min/Max | D35: =$B35*2080 -> 83200 | E35: 83200
